<?xml version="1.0" ?>
<!-- =================================================================================== -->
<!-- |    This document was autogenerated by xacro from ur5_robot.urdf.xacro           | -->
<!-- |    EDITING THIS FILE BY HAND IS NOT RECOMMENDED                                 | -->
<!-- =================================================================================== -->
<robot name="ur5">
  <link name="base_link">
    <visual>
      <geometry>
        <mesh filename="package://universal_robot_ign/resource/models/ur5/meshes/visual/base.dae"/>
      </geometry>
      <material name="LightGrey">
        <color rgba="0.7 0.7 0.7 1.0"/>
      </material>
    </visual>
    <collision>
      <geometry>
        <mesh filename="package://universal_robot_ign/resource/models/ur5/meshes/collision/base.stl"/>
      </geometry>
    </collision>
    <inertial>
      <mass value="4.0"/>
      <origin rpy="0 0 0" xyz="0.0 0.0 0.0"/>
      <inertia ixx="0.00443333156" ixy="0.0" ixz="0.0" iyy="0.00443333156" iyz="0.0" izz="0.0072"/>
    </inertial>
  </link>
  <joint name="shoulder_pan_joint" type="revolute">
    <parent link="base_link"/>
    <child link="shoulder_link"/>
    <origin rpy="0.0 0.0 0.0" xyz="0.0 0.0 0.089159"/>
    <axis xyz="0 0 1"/>
    <limit effort="150.0" lower="-6.283185307179586" upper="6.283185307179586" velocity="3.15"/>
    <dynamics damping="0.0" friction="0.0"/>
  </joint>
  <link name="shoulder_link">
    <visual>
      <geometry>
        <mesh filename="package://universal_robot_ign/resource/models/ur5/meshes/visual/shoulder.dae"/>
      </geometry>
      <material name="LightGrey">
        <color rgba="0.7 0.7 0.7 1.0"/>
      </material>
    </visual>
    <collision>
      <geometry>
        <mesh filename="package://universal_robot_ign/resource/models/ur5/meshes/collision/shoulder.stl"/>
      </geometry>
    </collision>
    <inertial>
      <mass value="3.7"/>
      <origin rpy="0 0 0" xyz="0.0 0.0 0.0"/>
      <inertia ixx="0.010267495893" ixy="0.0" ixz="0.0" iyy="0.010267495893" iyz="0.0" izz="0.00666"/>
    </inertial>
  </link>
  <joint name="shoulder_lift_joint" type="revolute">
    <parent link="shoulder_link"/>
    <child link="upper_arm_link"/>
    <origin rpy="0.0 1.5707963267948966 0.0" xyz="0.0 0.13585 0.0"/>
    <axis xyz="0 1 0"/>
    <limit effort="150.0" lower="-6.283185307179586" upper="6.283185307179586" velocity="3.15"/>
    <dynamics damping="0.0" friction="0.0"/>
  </joint>
  <link name="upper_arm_link">
    <visual>
      <geometry>
        <mesh filename="package://universal_robot_ign/resource/models/ur5/meshes/visual/upperarm.dae"/>
      </geometry>
      <material name="LightGrey">
        <color rgba="0.7 0.7 0.7 1.0"/>
      </material>
    </visual>
    <collision>
      <geometry>
        <mesh filename="package://universal_robot_ign/resource/models/ur5/meshes/collision/upperarm.stl"/>
      </geometry>
    </collision>
    <inertial>
      <mass value="8.393"/>
      <origin rpy="0 0 0" xyz="0.0 0.0 0.28"/>
      <inertia ixx="0.22689067591036005" ixy="0.0" ixz="0.0" iyy="0.22689067591036005" iyz="0.0" izz="0.0151074"/>
    </inertial>
  </link>
  <joint name="elbow_joint" type="revolute">
    <parent link="upper_arm_link"/>
    <child link="forearm_link"/>
    <origin rpy="0.0 0.0 0.0" xyz="0.0 -0.1197 0.425"/>
    <axis xyz="0 1 0"/>
    <limit effort="150.0" lower="-3.141592653589793" upper="3.141592653589793" velocity="3.15"/>
    <dynamics damping="0.0" friction="0.0"/>
  </joint>
  <link name="forearm_link">
    <visual>
      <geometry>
        <mesh filename="package://universal_robot_ign/resource/models/ur5/meshes/visual/forearm.dae"/>
      </geometry>
      <material name="LightGrey">
        <color rgba="0.7 0.7 0.7 1.0"/>
      </material>
    </visual>
    <collision>
      <geometry>
        <mesh filename="package://universal_robot_ign/resource/models/ur5/meshes/collision/forearm.stl"/>
      </geometry>
    </collision>
    <inertial>
      <mass value="2.275"/>
      <origin rpy="0 0 0" xyz="0.0 0.0 0.196125"/>
      <inertia ixx="0.03121679102890359" ixy="0.0" ixz="0.0" iyy="0.03121679102890359" iyz="0.0" izz="0.004095"/>
    </inertial>
  </link>
  <joint name="wrist_1_joint" type="revolute">
    <parent link="forearm_link"/>
    <child link="wrist_1_link"/>
    <origin rpy="0.0 1.5707963267948966 0.0" xyz="0.0 0.0 0.39225"/>
    <axis xyz="0 1 0"/>
    <limit effort="28.0" lower="-6.283185307179586" upper="6.283185307179586" velocity="3.2"/>
    <dynamics damping="0.0" friction="0.0"/>
  </joint>
  <link name="wrist_1_link">
    <visual>
      <geometry>
        <mesh filename="package://universal_robot_ign/resource/models/ur5/meshes/visual/wrist1.dae"/>
      </geometry>
      <material name="LightGrey">
        <color rgba="0.7 0.7 0.7 1.0"/>
      </material>
    </visual>
    <collision>
      <geometry>
        <mesh filename="package://universal_robot_ign/resource/models/ur5/meshes/collision/wrist1.stl"/>
      </geometry>
    </collision>
    <inertial>
      <mass value="1.219"/>
      <origin rpy="0 0 0" xyz="0.0 0.093 0.0"/>
      <inertia ixx="0.0025598989760400002" ixy="0.0" ixz="0.0" iyy="0.0025598989760400002" iyz="0.0" izz="0.0021942"/>
    </inertial>
  </link>
  <joint name="wrist_2_joint" type="revolute">
    <parent link="wrist_1_link"/>
    <child link="wrist_2_link"/>
    <origin rpy="0.0 0.0 0.0" xyz="0.0 0.093 0.0"/>
    <axis xyz="0 0 1"/>
    <limit effort="28.0" lower="-6.283185307179586" upper="6.283185307179586" velocity="3.2"/>
    <dynamics damping="0.0" friction="0.0"/>
  </joint>
  <link name="wrist_2_link">
    <visual>
      <geometry>
        <mesh filename="package://universal_robot_ign/resource/models/ur5/meshes/visual/wrist2.dae"/>
      </geometry>
      <material name="LightGrey">
        <color rgba="0.7 0.7 0.7 1.0"/>
      </material>
    </visual>
    <collision>
      <geometry>
        <mesh filename="package://universal_robot_ign/resource/models/ur5/meshes/collision/wrist2.stl"/>
      </geometry>
    </collision>
    <inertial>
      <mass value="1.219"/>
      <origin rpy="0 0 0" xyz="0.0 0.0 0.09465"/>
      <inertia ixx="0.0025598989760400002" ixy="0.0" ixz="0.0" iyy="0.0025598989760400002" iyz="0.0" izz="0.0021942"/>
    </inertial>
  </link>
  <joint name="wrist_3_joint" type="revolute">
    <parent link="wrist_2_link"/>
    <child link="wrist_3_link"/>
    <origin rpy="0.0 0.0 0.0" xyz="0.0 0.0 0.09465"/>
    <axis xyz="0 1 0"/>
    <limit effort="28.0" lower="-6.283185307179586" upper="6.283185307179586" velocity="3.2"/>
    <dynamics damping="0.0" friction="0.0"/>
  </joint>
  <link name="wrist_3_link">
    <visual>
      <geometry>
        <mesh filename="package://universal_robot_ign/resource/models/ur5/meshes/visual/wrist3.dae"/>
      </geometry>
      <material name="LightGrey">
        <color rgba="0.7 0.7 0.7 1.0"/>
      </material>
    </visual>
    <collision>
      <geometry>
        <mesh filename="package://universal_robot_ign/resource/models/ur5/meshes/collision/wrist3.stl"/>
      </geometry>
    </collision>
    <inertial>
      <mass value="0.1879"/>
      <origin rpy="1.5707963267948966 0 0" xyz="0.0 0.06505 0.0"/>
      <inertia ixx="8.469589112163e-05" ixy="0.0" ixz="0.0" iyy="8.469589112163e-05" iyz="0.0" izz="0.0001321171875"/>
    </inertial>
  </link>
  <joint name="ee_fixed_joint" type="fixed">
    <parent link="wrist_3_link"/>
    <child link="ee_link"/>
    <origin rpy="0.0 0.0 1.5707963267948966" xyz="0.0 0.0823 0.0"/>
  </joint>
  <link name="ee_link">
    <collision>
      <geometry>
        <box size="0.01 0.01 0.01"/>
      </geometry>
      <origin rpy="0 0 0" xyz="-0.01 0 0"/>
    </collision>
  </link>
<!--  Robotiq gripper-->
  <joint name="ur10_robotiq140_joint" type="fixed">
    <parent link="ee_link"/>
    <child link="robotiq_arg2f_base_link"/>
    <origin xyz="0 0.0 0" rpy="0 1.570795 0"/>
  </joint>
  <link name="robotiq_arg2f_base_link">
    <inertial>
      <origin rpy="0 0 0" xyz="8.625E-08 -4.6583E-06 0.03145"/>
<!--      <mass value="0.22652"/>-->
      <mass value="2.2652"/>
      <inertia ixx="0.00020005" ixy="-4.2442E-10" ixz="-2.9069E-10" iyy="0.00017832" iyz="-3.4402E-08" izz="0.00013478"/>
    </inertial>
    <visual>
      <origin rpy="0 0 0" xyz="0 0 0"/>
      <geometry>
        <mesh filename="package://universal_robot_ign/resource/models/robotiq140/meshes/visual/robotiq_arg2f_base_link.stl"/>
      </geometry>
      <material name="">
        <color rgba="0.1 0.1 0.1 1"/>
      </material>
    </visual>
    <collision>
      <origin rpy="0 0 0" xyz="0 0 0"/>
      <geometry>
        <mesh filename="package://universal_robot_ign/resource/models/robotiq140/meshes/collision/robotiq_arg2f_base_link.stl"/>
      </geometry>
    </collision>
  </link>
  <link name="left_outer_knuckle">
    <inertial>
      <origin rpy="0 0 0" xyz="-0.000200000000003065 0.0199435877845359 0.0292245259211331"/>
      <mass value="0.00853198276973456"/>
      <inertia ixx="2.89328108496468E-06" ixy="-1.57935047237397E-19" ixz="-1.93980378593255E-19" iyy="1.86719750325683E-06" iyz="-1.21858577871576E-06" izz="1.21905238907251E-06"/>
    </inertial>
    <visual>
      <origin rpy="0 0 0" xyz="0 0 0"/>
      <geometry>
        <mesh filename="package://universal_robot_ign/resource/models/robotiq140/meshes/visual/robotiq_arg2f_140_outer_knuckle.stl"/>
      </geometry>
      <material name="">
        <color rgba="0.792156862745098 0.819607843137255 0.933333333333333 1"/>
      </material>
    </visual>
    <collision>
      <origin rpy="0 0 0" xyz="0 0 0"/>
      <geometry>
        <mesh filename="package://universal_robot_ign/resource/models/robotiq140/meshes/collision/robotiq_arg2f_140_outer_knuckle.stl"/>
      </geometry>
    </collision>
  </link>
  <link name="left_outer_finger">
    <inertial>
      <origin rpy="0 0 0" xyz="0.00030115855001899 0.0373907951953854 -0.0208027427000385"/>
      <mass value="0.022614240507152"/>
      <inertia ixx="1.52518312458174E-05" ixy="9.76583423954399E-10" ixz="-5.43838577022588E-10" iyy="6.17694243867776E-06" iyz="6.78636130740228E-06" izz="1.16494917907219E-05"/>
    </inertial>
    <visual>
      <origin rpy="0 0 0" xyz="0 0 0"/>
      <geometry>
        <mesh filename="package://universal_robot_ign/resource/models/robotiq140/meshes/visual/robotiq_arg2f_140_outer_finger.stl"/>
      </geometry>
      <material name="">
        <color rgba="0.1 0.1 0.1 1"/>
      </material>
    </visual>
    <collision>
      <origin rpy="0 0 0" xyz="0 0 0"/>
      <geometry>
        <mesh filename="package://universal_robot_ign/resource/models/robotiq140/meshes/collision/robotiq_arg2f_140_outer_finger.stl"/>
      </geometry>
    </collision>
  </link>
  <link name="left_inner_finger">
    <inertial>
      <origin rpy="0 0 0" xyz="0.000299999999999317 0.0160078233491243 -0.0136945669206257"/>
      <mass value="0.0104003125914103"/>
      <inertia ixx="2.71909453810972E-06" ixy="1.35402465472579E-21" ixz="-7.1817349065269E-22" iyy="7.69100314106116E-07" iyz="6.74715432769696E-07" izz="2.30315190420171E-06"/>
    </inertial>
    <visual>
      <origin rpy="0 0 0" xyz="0 0 0"/>
      <geometry>
        <mesh filename="package://universal_robot_ign/resource/models/robotiq140/meshes/visual/robotiq_arg2f_140_inner_finger.stl"/>
      </geometry>
      <material name="">
        <color rgba="0.1 0.1 0.1 1"/>
      </material>
    </visual>
    <collision>
      <origin rpy="0 0 0" xyz="0 0 0"/>
      <geometry>
        <mesh filename="package://universal_robot_ign/resource/models/robotiq140/meshes/collision/robotiq_arg2f_140_inner_finger.stl"/>
      </geometry>
    </collision>
  </link>
  <link name="left_inner_finger_pad">
    <visual>
      <origin rpy="0 0 0" xyz="0 0 0"/>
      <geometry>
        <box size="0.027 0.065 0.0075"/>
      </geometry>
      <material name="">
        <color rgba="0.9 0.9 0.9 1"/>
      </material>
    </visual>
    <collision>
      <origin rpy="0 0 0" xyz="0 0 0"/>
      <geometry>
        <box size="0.03 0.07 0.0075"/>
      </geometry>
      <material name="">
        <color rgba="0.9 0.0 0.0 1"/>
      </material>
    </collision>
  </link>
  <link name="left_inner_knuckle">
    <inertial>
      <origin rpy="0 0 0" xyz="0.000123011831763771 0.0507850843201817 0.00103968640075166"/>
      <mass value="0.0271177346495152"/>
      <inertia ixx="2.61910379223783E-05" ixy="-2.43616858946494E-07" ixz="-6.37789906117123E-09" iyy="2.8270243746167E-06" iyz="-5.37200748039765E-07" izz="2.83695868220296E-05"/>
    </inertial>
    <visual>
      <origin rpy="0 0 0" xyz="0 0 0"/>
      <geometry>
        <mesh filename="package://universal_robot_ign/resource/models/robotiq140/meshes/visual/robotiq_arg2f_140_inner_knuckle.stl"/>
      </geometry>
      <material name="">
        <color rgba="0.1 0.1 0.1 1"/>
      </material>
    </visual>
    <collision>
      <origin rpy="0 0 0" xyz="0 0 0"/>
      <geometry>
        <mesh filename="package://universal_robot_ign/resource/models/robotiq140/meshes/collision/robotiq_arg2f_140_inner_knuckle.stl"/>
      </geometry>
    </collision>
  </link>
  <link name="right_outer_knuckle">
    <inertial>
      <origin rpy="0 0 0" xyz="-0.000200000000003065 0.0199435877845359 0.0292245259211331"/>
      <mass value="0.00853198276973456"/>
      <inertia ixx="2.89328108496468E-06" ixy="-1.57935047237397E-19" ixz="-1.93980378593255E-19" iyy="1.86719750325683E-06" iyz="-1.21858577871576E-06" izz="1.21905238907251E-06"/>
    </inertial>
    <visual>
      <origin rpy="0 0 0" xyz="0 0 0"/>
      <geometry>
        <mesh filename="package://universal_robot_ign/resource/models/robotiq140/meshes/visual/robotiq_arg2f_140_outer_knuckle.stl"/>
      </geometry>
      <material name="">
        <color rgba="0.792156862745098 0.819607843137255 0.933333333333333 1"/>
      </material>
    </visual>
    <collision>
      <origin rpy="0 0 0" xyz="0 0 0"/>
      <geometry>
        <mesh filename="package://universal_robot_ign/resource/models/robotiq140/meshes/collision/robotiq_arg2f_140_outer_knuckle.stl"/>
      </geometry>
    </collision>
  </link>
  <link name="right_outer_finger">
    <inertial>
      <origin rpy="0 0 0" xyz="0.00030115855001899 0.0373907951953854 -0.0208027427000385"/>
      <mass value="0.022614240507152"/>
      <inertia ixx="1.52518312458174E-05" ixy="9.76583423954399E-10" ixz="-5.43838577022588E-10" iyy="6.17694243867776E-06" iyz="6.78636130740228E-06" izz="1.16494917907219E-05"/>
    </inertial>
    <visual>
      <origin rpy="0 0 0" xyz="0 0 0"/>
      <geometry>
        <mesh filename="package://universal_robot_ign/resource/models/robotiq140/meshes/visual/robotiq_arg2f_140_outer_finger.stl"/>
      </geometry>
      <material name="">
        <color rgba="0.1 0.1 0.1 1"/>
      </material>
    </visual>
    <collision>
      <origin rpy="0 0 0" xyz="0 0 0"/>
      <geometry>
        <mesh filename="package://universal_robot_ign/resource/models/robotiq140/meshes/collision/robotiq_arg2f_140_outer_finger.stl"/>
      </geometry>
    </collision>
  </link>
  <link name="right_inner_finger">
    <inertial>
      <origin rpy="0 0 0" xyz="0.000299999999999317 0.0160078233491243 -0.0136945669206257"/>
      <mass value="0.0104003125914103"/>
      <inertia ixx="2.71909453810972E-06" ixy="1.35402465472579E-21" ixz="-7.1817349065269E-22" iyy="7.69100314106116E-07" iyz="6.74715432769696E-07" izz="2.30315190420171E-06"/>
    </inertial>
    <visual>
      <origin rpy="0 0 0" xyz="0 0 0"/>
      <geometry>
        <mesh filename="package://universal_robot_ign/resource/models/robotiq140/meshes/visual/robotiq_arg2f_140_inner_finger.stl"/>
      </geometry>
      <material name="">
        <color rgba="0.1 0.1 0.1 1"/>
      </material>
    </visual>
    <collision>
      <origin rpy="0 0 0" xyz="0 0 0"/>
      <geometry>
        <mesh filename="package://universal_robot_ign/resource/models/robotiq140/meshes/collision/robotiq_arg2f_140_inner_finger.stl"/>
      </geometry>
    </collision>
  </link>
  <link name="right_inner_finger_pad">
    <visual>
      <origin rpy="0 0 0" xyz="0 0 0"/>
      <geometry>
        <box size="0.027 0.065 0.0075"/>
      </geometry>
      <material name="">
        <color rgba="0.9 0.9 0.9 1"/>
      </material>
    </visual>
    <collision>
      <origin rpy="0 0 0" xyz="0 0 0"/>
      <geometry>
        <box size="0.03 0.07 0.0075"/>
      </geometry>
      <material name="">
        <color rgba="0.9 0.0 0.0 1"/>
      </material>
    </collision>
  </link>
  <link name="right_inner_knuckle">
    <inertial>
      <origin rpy="0 0 0" xyz="0.000123011831763771 0.0507850843201817 0.00103968640075166"/>
      <mass value="0.0271177346495152"/>
      <inertia ixx="2.61910379223783E-05" ixy="-2.43616858946494E-07" ixz="-6.37789906117123E-09" iyy="2.8270243746167E-06" iyz="-5.37200748039765E-07" izz="2.83695868220296E-05"/>
    </inertial>
    <visual>
      <origin rpy="0 0 0" xyz="0 0 0"/>
      <geometry>
        <mesh filename="package://universal_robot_ign/resource/models/robotiq140/meshes/visual/robotiq_arg2f_140_inner_knuckle.stl"/>
      </geometry>
      <material name="">
        <color rgba="0.1 0.1 0.1 1"/>
      </material>
    </visual>
    <collision>
      <origin rpy="0 0 0" xyz="0 0 0"/>
      <geometry>
        <mesh filename="package://universal_robot_ign/resource/models/robotiq140/meshes/collision/robotiq_arg2f_140_inner_knuckle.stl"/>
      </geometry>
    </collision>
  </link>
  <joint name="finger_joint" type="revolute">
    <origin rpy="2.2957963267948966 0 0" xyz="0 -0.030601 0.054905"/>
    <parent link="robotiq_arg2f_base_link"/>
    <child link="left_outer_knuckle"/>
    <axis xyz="-1 0 0"/>
    <limit effort="1000" lower="0" upper="0.7" velocity="2.0"/>
  </joint>
  <joint name="left_outer_finger_joint" type="fixed">
    <origin rpy="0 0 0" xyz="0 0.01821998610742 0.0260018192872234"/>
    <parent link="left_outer_knuckle"/>
    <child link="left_outer_finger"/>
    <axis xyz="1 0 0"/>
  </joint>
  <joint name="left_inner_knuckle_joint" type="revolute">
    <origin rpy="2.2957963267948966 0 0.0" xyz="0 -0.0127 0.06142"/>
    <parent link="robotiq_arg2f_base_link"/>
    <child link="left_inner_knuckle"/>
    <axis xyz="1 0 0"/>
    <limit effort="1000" lower="-0.8757" upper="0.8757" velocity="2.0"/>
    <mimic joint="finger_joint" multiplier="-1" offset="0"/>
  </joint>
  <joint name="left_inner_finger_joint" type="revolute">
    <origin rpy="-0.725 0 0" xyz="0 0.0817554015893473 -0.0282203446692936"/>
    <parent link="left_outer_finger"/>
    <child link="left_inner_finger"/>
    <axis xyz="1 0 0"/>
    <limit effort="1000" lower="-0.8757" upper="0.8757" velocity="2.0"/>
    <mimic joint="finger_joint" multiplier="1" offset="0"/>
  </joint>
  <joint name="left_inner_finger_pad_joint" type="fixed">
    <origin rpy="0 0 0" xyz="0 0.0457554015893473 -0.0272203446692936"/>
    <parent link="left_inner_finger"/>
    <child link="left_inner_finger_pad"/>
    <axis xyz="0 0 1"/>
  </joint>
  <joint name="right_outer_knuckle_joint" type="revolute">
    <origin rpy="2.2957963267948966 0 3.141592653589793" xyz="0 0.030601 0.054905"/>
    <parent link="robotiq_arg2f_base_link"/>
    <child link="right_outer_knuckle"/>
    <axis xyz="1 0 0"/>
    <limit effort="1000" lower="-0.725" upper="0.725" velocity="2.0"/>
    <mimic joint="finger_joint" multiplier="-1" offset="0"/>
  </joint>
  <joint name="right_outer_finger_joint" type="fixed">
    <origin rpy="0 0 0" xyz="0 0.01821998610742 0.0260018192872234"/>
    <parent link="right_outer_knuckle"/>
    <child link="right_outer_finger"/>
    <axis xyz="1 0 0"/>
  </joint>
  <joint name="right_inner_knuckle_joint" type="revolute">
    <origin rpy="2.2957963267948966 0 -3.141592653589793" xyz="0 0.0127 0.06142"/>
    <parent link="robotiq_arg2f_base_link"/>
    <child link="right_inner_knuckle"/>
    <axis xyz="1 0 0"/>
    <limit effort="1000" lower="-0.8757" upper="0.8757" velocity="2.0"/>
    <mimic joint="finger_joint" multiplier="-1" offset="0"/>
  </joint>
  <joint name="right_inner_finger_joint" type="revolute">
    <origin rpy="-0.725 0 0" xyz="0 0.0817554015893473 -0.0282203446692936"/>
    <parent link="right_outer_finger"/>
    <child link="right_inner_finger"/>
    <axis xyz="1 0 0"/>
    <limit effort="1000" lower="-0.8757" upper="0.8757" velocity="2.0"/>
    <mimic joint="finger_joint" multiplier="1" offset="0"/>
  </joint>
  <joint name="right_inner_finger_pad_joint" type="fixed">
    <origin rpy="0 0 0" xyz="0 0.0457554015893473 -0.0272203446692936"/>
    <parent link="right_inner_finger"/>
    <child link="right_inner_finger_pad"/>
    <axis xyz="0 0 1"/>
  </joint>
  <transmission name="shoulder_pan_trans">
    <type>transmission_interface/SimpleTransmission</type>
    <joint name="shoulder_pan_joint">
      <hardwareInterface>hardware_interface/PositionJointInterface</hardwareInterface>
    </joint>
    <actuator name="shoulder_pan_motor">
      <mechanicalReduction>1</mechanicalReduction>
    </actuator>
  </transmission>
  <transmission name="shoulder_lift_trans">
    <type>transmission_interface/SimpleTransmission</type>
    <joint name="shoulder_lift_joint">
      <hardwareInterface>hardware_interface/PositionJointInterface</hardwareInterface>
    </joint>
    <actuator name="shoulder_lift_motor">
      <mechanicalReduction>1</mechanicalReduction>
    </actuator>
  </transmission>
  <transmission name="elbow_trans">
    <type>transmission_interface/SimpleTransmission</type>
    <joint name="elbow_joint">
      <hardwareInterface>hardware_interface/PositionJointInterface</hardwareInterface>
    </joint>
    <actuator name="elbow_motor">
      <mechanicalReduction>1</mechanicalReduction>
    </actuator>
  </transmission>
  <transmission name="wrist_1_trans">
    <type>transmission_interface/SimpleTransmission</type>
    <joint name="wrist_1_joint">
      <hardwareInterface>hardware_interface/PositionJointInterface</hardwareInterface>
    </joint>
    <actuator name="wrist_1_motor">
      <mechanicalReduction>1</mechanicalReduction>
    </actuator>
  </transmission>
  <transmission name="wrist_2_trans">
    <type>transmission_interface/SimpleTransmission</type>
    <joint name="wrist_2_joint">
      <hardwareInterface>hardware_interface/PositionJointInterface</hardwareInterface>
    </joint>
    <actuator name="wrist_2_motor">
      <mechanicalReduction>1</mechanicalReduction>
    </actuator>
  </transmission>
  <transmission name="wrist_3_trans">
    <type>transmission_interface/SimpleTransmission</type>
    <joint name="wrist_3_joint">
      <hardwareInterface>hardware_interface/PositionJointInterface</hardwareInterface>
    </joint>
    <actuator name="wrist_3_motor">
      <mechanicalReduction>1</mechanicalReduction>
    </actuator>
  </transmission>
<!--  <gazebo reference="shoulder_link">-->
<!--    <selfCollide>true</selfCollide>-->
<!--  </gazebo>-->
<!--  <gazebo reference="upper_arm_link">-->
<!--    <selfCollide>true</selfCollide>-->
<!--  </gazebo>-->
<!--  <gazebo reference="forearm_link">-->
<!--    <selfCollide>true</selfCollide>-->
<!--  </gazebo>-->
<!--  <gazebo reference="wrist_1_link">-->
<!--    <selfCollide>true</selfCollide>-->
<!--  </gazebo>-->
<!--  <gazebo reference="wrist_3_link">-->
<!--    <selfCollide>true</selfCollide>-->
<!--  </gazebo>-->
<!--  <gazebo reference="wrist_2_link">-->
<!--    <selfCollide>true</selfCollide>-->
<!--  </gazebo>-->
<!--  <gazebo reference="ee_link">-->
<!--    <selfCollide>true</selfCollide>-->
<!--  </gazebo>-->
  <!-- ROS base_link to UR 'Base' Coordinates transform -->
  <link name="base"/>
  <joint name="base_link-base_fixed_joint" type="fixed">
    <!-- NOTE: this rotation is only needed as long as base_link itself is
                 not corrected wrt the real robot (ie: rotated over 180
                 degrees)
      -->
    <origin rpy="0 0 -3.141592653589793" xyz="0 0 0"/>
    <parent link="base_link"/>
    <child link="base"/>
  </joint>
  <!-- Frame coincident with all-zeros TCP on UR controller -->
  <link name="tool0"/>
  <joint name="wrist_3_link-tool0_fixed_joint" type="fixed">
    <origin rpy="-1.5707963267948966 0 0" xyz="0 0.0823 0"/>
    <parent link="wrist_3_link"/>
    <child link="tool0"/>
  </joint>
<!--  ros2 control tags-->
  <ros2_control name="URPositionHardwareInterface" type="system">
    <hardware>
        <plugin>ur_robot_driver/URPositionHardwareInterface</plugin>
        <param name="robot_ip">x.x.x.x</param>
        <param name="script_filename">""</param>
        <param name="output_recipe_filename">""</param>
        <param name="input_recipe_filename">""</param>
        <param name="headless_mode">false</param>
        <param name="reverse_port">50001</param>
        <param name="script_sender_port">50002</param>
        <param name="tf_prefix">""</param>
        <param name="non_blocking_read">0</param>
        <param name="servoj_gain">2000</param>
        <param name="servoj_lookahead_time">0.03</param>
        <param name="use_tool_communication">false</param>
        <param name="kinematics/hash">""</param>
        <param name="tool_voltage">0</param>
        <param name="tool_parity">0</param>
        <param name="tool_baud_rate">115200</param>
        <param name="tool_stop_bits">1</param>
        <param name="tool_rx_idle_chars">1.5</param>
        <param name="tool_tx_idle_chars">3.5</param>
        <param name="tool_device_name">/tmp/ttyUR</param>
        <param name="tool_tcp_port">54321</param>
<!--        <param name="control_mode">velocity</param>-->
        <param name="control_mode">position</param>
    </hardware>
    <joint name="shoulder_pan_joint">
      <command_interface name="position">
        <param name="min">-6.283185</param>
        <param name="max">6.283185</param>
      </command_interface>
      <command_interface name="velocity">
        <param name="min">-3.15</param>
        <param name="max">3.15</param>
      </command_interface>
      <state_interface name="position"/>
      <state_interface name="velocity"/>
      <state_interface name="effort"/>
      <param name="initial_position">0.0</param>  <!-- initial position for the FakeSystem -->
    </joint>
    <joint name="shoulder_lift_joint">
      <command_interface name="position">
        <param name="min">-6.283185</param>
        <param name="max">6.283185</param>
      </command_interface>
      <command_interface name="velocity">
        <param name="min">-3.15</param>
        <param name="max">3.15</param>
      </command_interface>
      <state_interface name="position"/>
      <state_interface name="velocity"/>
      <state_interface name="effort"/>
      <param name="initial_position">-1.57</param>  <!-- initial position for the FakeSystem -->
    </joint>
    <joint name="elbow_joint">
      <command_interface name="position">
        <param name="min">-3.14159</param>
        <param name="max">3.14159</param>
      </command_interface>
      <command_interface name="velocity">
        <param name="min">-3.15</param>
        <param name="max">3.15</param>
      </command_interface>
      <state_interface name="position"/>
      <state_interface name="velocity"/>
      <state_interface name="effort"/>
      <param name="initial_position">0.0</param>  <!-- initial position for the FakeSystem -->
    </joint>
    <joint name="wrist_1_joint">
      <command_interface name="position">
        <param name="min">-6.283185</param>
        <param name="max">6.283185</param>
      </command_interface>
      <command_interface name="velocity">
        <param name="min">-3.2</param>
        <param name="max">3.2</param>
      </command_interface>
      <state_interface name="position"/>
      <state_interface name="velocity"/>
      <state_interface name="effort"/>
      <param name="initial_position">-1.57</param>  <!-- initial position for the FakeSystem -->
    </joint>
    <joint name="wrist_2_joint">
      <command_interface name="position">
        <param name="min">-6.283185</param>
        <param name="max">6.283185</param>
      </command_interface>
      <command_interface name="velocity">
        <param name="min">-3.2</param>
        <param name="max">3.2</param>
      </command_interface>
      <state_interface name="position"/>
      <state_interface name="velocity"/>
      <state_interface name="effort"/>
      <param name="initial_position">0.0</param>  <!-- initial position for the FakeSystem -->
    </joint>
    <joint name="wrist_3_joint">
      <command_interface name="position">
        <param name="min">-6.283185</param>
        <param name="max">6.283185</param>
      </command_interface>
      <command_interface name="velocity">
        <param name="min">-3.2</param>
        <param name="max">3.2</param>
      </command_interface>
      <state_interface name="position"/>
      <state_interface name="velocity"/>
      <state_interface name="effort"/>
      <param name="initial_position">0.0</param>  <!-- initial position for the FakeSystem -->
    </joint>
<!--  add robotiq gripper  -->
    <joint name="finger_joint">
      <command_interface name="position">
        <param name="min">0.0</param>
        <param name="max">0.7</param>
      </command_interface>
      <command_interface name="velocity">
        <param name="min">-2.0</param>
        <param name="max">2.0</param>
      </command_interface>
      <state_interface name="position"/>
      <state_interface name="velocity"/>
      <state_interface name="effort"/>
      <param name="initial_position">0.0</param>  <!-- initial position for the FakeSystem -->
    </joint>
    <joint name="left_inner_knuckle_joint">
      <command_interface name="position">
        <param name="min">-0.8757</param>
        <param name="max">0.8757</param>
      </command_interface>
      <command_interface name="velocity">
        <param name="min">-2.0</param>
        <param name="max">2.0</param>
      </command_interface>
      <state_interface name="position"/>
      <state_interface name="velocity"/>
      <state_interface name="effort"/>
      <param name="initial_position">0.0</param>  <!-- initial position for the FakeSystem -->
    </joint>
    <joint name="left_inner_finger_joint">
      <command_interface name="position">
        <param name="min">-0.8757</param>
        <param name="max">0.8757</param>
      </command_interface>
      <command_interface name="velocity">
        <param name="min">-2.0</param>
        <param name="max">2.0</param>
      </command_interface>
      <state_interface name="position"/>
      <state_interface name="velocity"/>
      <state_interface name="effort"/>
      <param name="initial_position">0.0</param>  <!-- initial position for the FakeSystem -->
    </joint>
    <joint name="right_outer_knuckle_joint">
      <command_interface name="position">
        <param name="min">-0.725</param>
        <param name="max">0.725</param>
      </command_interface>
      <command_interface name="velocity">
        <param name="min">-2.0</param>
        <param name="max">2.0</param>
      </command_interface>
      <state_interface name="position"/>
      <state_interface name="velocity"/>
      <state_interface name="effort"/>
      <param name="initial_position">0.0</param>  <!-- initial position for the FakeSystem -->
    </joint>
    <joint name="right_inner_knuckle_joint">
      <command_interface name="position">
        <param name="min">-0.8757</param>
        <param name="max">0.8757</param>
      </command_interface>
      <command_interface name="velocity">
        <param name="min">-2.0</param>
        <param name="max">2.0</param>
      </command_interface>
      <state_interface name="position"/>
      <state_interface name="velocity"/>
      <state_interface name="effort"/>
      <param name="initial_position">0.0</param>  <!-- initial position for the FakeSystem -->
    </joint>
    <joint name="right_inner_finger_joint">
      <command_interface name="position">
        <param name="min">-0.8757</param>
        <param name="max">0.8757</param>
      </command_interface>
      <command_interface name="velocity">
        <param name="min">-2.0</param>
        <param name="max">2.0</param>
      </command_interface>
      <state_interface name="position"/>
      <state_interface name="velocity"/>
      <state_interface name="effort"/>
      <param name="initial_position">0.0</param>  <!-- initial position for the FakeSystem -->
    </joint>
    <!--  end robotiq gripper  -->
    <sensor name="tcp_fts_sensor">
      <state_interface name="force.x"/>
      <state_interface name="force.y"/>
      <state_interface name="force.z"/>
      <state_interface name="torque.x"/>
      <state_interface name="torque.y"/>
      <state_interface name="torque.z"/>
    </sensor>
    <!-- NOTE The following are joints used only for testing with fake hardware and will change in the future -->
    <joint name="speed_scaling">
      <state_interface name="speed_scaling_factor"/>
      <param name="initial_speed_scaling_factor">1</param>
      <command_interface name="target_speed_fraction_cmd"/>
      <command_interface name="target_speed_fraction_async_success"/>
    </joint>
    <joint name="gpio">
      <command_interface name="standard_digital_output_cmd_0"/>
      <command_interface name="standard_digital_output_cmd_1"/>
      <command_interface name="standard_digital_output_cmd_2"/>
      <command_interface name="standard_digital_output_cmd_3"/>
      <command_interface name="standard_digital_output_cmd_4"/>
      <command_interface name="standard_digital_output_cmd_5"/>
      <command_interface name="standard_digital_output_cmd_6"/>
      <command_interface name="standard_digital_output_cmd_7"/>
      <command_interface name="standard_digital_output_cmd_8"/>
      <command_interface name="standard_digital_output_cmd_9"/>
      <command_interface name="standard_digital_output_cmd_10"/>
      <command_interface name="standard_digital_output_cmd_11"/>
      <command_interface name="standard_digital_output_cmd_12"/>
      <command_interface name="standard_digital_output_cmd_13"/>
      <command_interface name="standard_digital_output_cmd_14"/>
      <command_interface name="standard_digital_output_cmd_15"/>
      <command_interface name="standard_digital_output_cmd_16"/>
      <command_interface name="standard_digital_output_cmd_17"/>
      <command_interface name="standard_analog_output_cmd_0"/>
      <command_interface name="standard_analog_output_cmd_1"/>
      <command_interface name="io_async_success"/>
      <state_interface name="digital_output_0"/>
      <state_interface name="digital_output_1"/>
      <state_interface name="digital_output_2"/>
      <state_interface name="digital_output_3"/>
      <state_interface name="digital_output_4"/>
      <state_interface name="digital_output_5"/>
      <state_interface name="digital_output_6"/>
      <state_interface name="digital_output_7"/>
      <state_interface name="digital_output_8"/>
      <state_interface name="digital_output_9"/>
      <state_interface name="digital_output_10"/>
      <state_interface name="digital_output_11"/>
      <state_interface name="digital_output_12"/>
      <state_interface name="digital_output_13"/>
      <state_interface name="digital_output_14"/>
      <state_interface name="digital_output_15"/>
      <state_interface name="digital_output_16"/>
      <state_interface name="digital_output_17"/>
      <state_interface name="digital_input_0"/>
      <state_interface name="digital_input_1"/>
      <state_interface name="digital_input_2"/>
      <state_interface name="digital_input_3"/>
      <state_interface name="digital_input_4"/>
      <state_interface name="digital_input_5"/>
      <state_interface name="digital_input_6"/>
      <state_interface name="digital_input_7"/>
      <state_interface name="digital_input_8"/>
      <state_interface name="digital_input_9"/>
      <state_interface name="digital_input_10"/>
      <state_interface name="digital_input_11"/>
      <state_interface name="digital_input_12"/>
      <state_interface name="digital_input_13"/>
      <state_interface name="digital_input_14"/>
      <state_interface name="digital_input_15"/>
      <state_interface name="digital_input_16"/>
      <state_interface name="digital_input_17"/>
      <state_interface name="standard_analog_output_0"/>
      <state_interface name="standard_analog_output_1"/>
      <state_interface name="standard_analog_input_0"/>
      <state_interface name="standard_analog_input_1"/>
      <state_interface name="analog_io_type_0"/>
      <state_interface name="analog_io_type_1"/>
      <state_interface name="analog_io_type_2"/>
      <state_interface name="analog_io_type_3"/>
      <state_interface name="tool_mode"/>
      <state_interface name="tool_output_voltage"/>
      <state_interface name="tool_output_current"/>
      <state_interface name="tool_temperature"/>
      <state_interface name="tool_analog_input_0"/>
      <state_interface name="tool_analog_input_1"/>
      <state_interface name="tool_analog_input_type_0"/>
      <state_interface name="tool_analog_input_type_1"/>
      <state_interface name="robot_mode"/>
      <state_interface name="robot_status_bit_0"/>
      <state_interface name="robot_status_bit_1"/>
      <state_interface name="robot_status_bit_2"/>
      <state_interface name="robot_status_bit_3"/>
      <state_interface name="safety_mode"/>
      <state_interface name="safety_status_bit_0"/>
      <state_interface name="safety_status_bit_1"/>
      <state_interface name="safety_status_bit_2"/>
      <state_interface name="safety_status_bit_3"/>
      <state_interface name="safety_status_bit_4"/>
      <state_interface name="safety_status_bit_5"/>
      <state_interface name="safety_status_bit_6"/>
      <state_interface name="safety_status_bit_7"/>
      <state_interface name="safety_status_bit_8"/>
      <state_interface name="safety_status_bit_9"/>
      <state_interface name="safety_status_bit_10"/>
    </joint>
    <joint name="resend_robot_program">
      <command_interface name="resend_robot_program_cmd"/>
      <command_interface name="resend_robot_program_async_success"/>
    </joint>
    <joint name="system_interface">
      <state_interface name="initialized"/>
    </joint>
  </ros2_control>
</robot>
